[2024-12-06T19:11:37.636+0000] {taskinstance.py:1956} INFO - Dependencies all met for dep_context=non-requeueable deps ti=<TaskInstance: weather_dag.is_weather_api_ready manual__2024-12-06T19:09:34.321126+00:00 [queued]>
[2024-12-06T19:11:37.642+0000] {taskinstance.py:1956} INFO - Dependencies all met for dep_context=requeueable deps ti=<TaskInstance: weather_dag.is_weather_api_ready manual__2024-12-06T19:09:34.321126+00:00 [queued]>
[2024-12-06T19:11:37.642+0000] {taskinstance.py:2170} INFO - Starting attempt 2 of 3
[2024-12-06T19:11:37.649+0000] {taskinstance.py:2191} INFO - Executing <Task(HttpSensor): is_weather_api_ready> on 2024-12-06 19:09:34.321126+00:00
[2024-12-06T19:11:37.653+0000] {standard_task_runner.py:60} INFO - Started process 1178 to run task
[2024-12-06T19:11:37.656+0000] {standard_task_runner.py:87} INFO - Running: ['***', 'tasks', 'run', 'weather_dag', 'is_weather_api_ready', 'manual__2024-12-06T19:09:34.321126+00:00', '--job-id', '3', '--raw', '--subdir', 'DAGS_FOLDER/extract.py', '--cfg-path', '/tmp/tmpdg2hzws6']
[2024-12-06T19:11:37.657+0000] {standard_task_runner.py:88} INFO - Job 3: Subtask is_weather_api_ready
[2024-12-06T19:11:37.668+0000] {warnings.py:109} WARNING - /home/***/.local/lib/python3.8/site-packages/***/settings.py:194: DeprecationWarning: The sql_alchemy_conn option in [core] has been moved to the sql_alchemy_conn option in [database] - the old setting has been used, but please update your config.
  SQL_ALCHEMY_CONN = conf.get("database", "SQL_ALCHEMY_CONN")

[2024-12-06T19:11:37.696+0000] {task_command.py:423} INFO - Running <TaskInstance: weather_dag.is_weather_api_ready manual__2024-12-06T19:09:34.321126+00:00 [running]> on host 8a5e48d7ee4d
[2024-12-06T19:11:37.749+0000] {taskinstance.py:2480} INFO - Exporting env vars: AIRFLOW_CTX_DAG_EMAIL='thiernosidybah232@gmail.com' AIRFLOW_CTX_DAG_OWNER='***' AIRFLOW_CTX_DAG_ID='weather_dag' AIRFLOW_CTX_TASK_ID='is_weather_api_ready' AIRFLOW_CTX_EXECUTION_DATE='2024-12-06T19:09:34.321126+00:00' AIRFLOW_CTX_TRY_NUMBER='2' AIRFLOW_CTX_DAG_RUN_ID='manual__2024-12-06T19:09:34.321126+00:00'
[2024-12-06T19:11:37.750+0000] {http.py:130} INFO - Poking: https://api.openweathermap.org/data/2.5/weather?q=Nantes&appid=92a2228961d1701676a43daabb355f4d
[2024-12-06T19:11:37.764+0000] {taskinstance.py:2698} ERROR - Task failed with exception
Traceback (most recent call last):
  File "/home/airflow/.local/lib/python3.8/site-packages/airflow/models/taskinstance.py", line 433, in _execute_task
    result = execute_callable(context=context, **execute_callable_kwargs)
  File "/home/airflow/.local/lib/python3.8/site-packages/airflow/sensors/base.py", line 265, in execute
    raise e
  File "/home/airflow/.local/lib/python3.8/site-packages/airflow/sensors/base.py", line 247, in execute
    poke_return = self.poke(context)
  File "/home/airflow/.local/lib/python3.8/site-packages/airflow/providers/http/sensors/http.py", line 148, in poke
    raise exc
  File "/home/airflow/.local/lib/python3.8/site-packages/airflow/providers/http/sensors/http.py", line 132, in poke
    response = hook.run(
  File "/home/airflow/.local/lib/python3.8/site-packages/airflow/providers/http/hooks/http.py", line 145, in run
    session = self.get_conn(headers)
  File "/home/airflow/.local/lib/python3.8/site-packages/airflow/providers/http/hooks/http.py", line 98, in get_conn
    conn = self.get_connection(self.http_conn_id)
  File "/home/airflow/.local/lib/python3.8/site-packages/airflow/hooks/base.py", line 82, in get_connection
    conn = Connection.get_connection_from_secrets(conn_id)
  File "/home/airflow/.local/lib/python3.8/site-packages/airflow/models/connection.py", line 479, in get_connection_from_secrets
    raise AirflowNotFoundException(f"The conn_id `{conn_id}` isn't defined")
airflow.exceptions.AirflowNotFoundException: The conn_id `weathermap_api` isn't defined
[2024-12-06T19:11:37.766+0000] {taskinstance.py:1138} INFO - Marking task as UP_FOR_RETRY. dag_id=weather_dag, task_id=is_weather_api_ready, execution_date=20241206T190934, start_date=20241206T191137, end_date=20241206T191137
[2024-12-06T19:11:37.774+0000] {standard_task_runner.py:107} ERROR - Failed to execute job 3 for task is_weather_api_ready (The conn_id `weathermap_api` isn't defined; 1178)
[2024-12-06T19:11:37.787+0000] {local_task_job_runner.py:234} INFO - Task exited with return code 1
[2024-12-06T19:11:37.802+0000] {taskinstance.py:3280} INFO - 0 downstream tasks scheduled from follow-on schedule check
