[2024-12-07T18:47:19.832+0000] {taskinstance.py:1956} INFO - Dependencies all met for dep_context=non-requeueable deps ti=<TaskInstance: weather_dag.insert_book_data manual__2024-12-07T18:45:09.543580+00:00 [queued]>
[2024-12-07T18:47:19.841+0000] {taskinstance.py:1956} INFO - Dependencies all met for dep_context=requeueable deps ti=<TaskInstance: weather_dag.insert_book_data manual__2024-12-07T18:45:09.543580+00:00 [queued]>
[2024-12-07T18:47:19.841+0000] {taskinstance.py:2170} INFO - Starting attempt 3 of 3
[2024-12-07T18:47:19.850+0000] {taskinstance.py:2191} INFO - Executing <Task(PythonOperator): insert_book_data> on 2024-12-07 18:45:09.543580+00:00
[2024-12-07T18:47:19.854+0000] {standard_task_runner.py:60} INFO - Started process 10604 to run task
[2024-12-07T18:47:19.857+0000] {standard_task_runner.py:87} INFO - Running: ['***', 'tasks', 'run', 'weather_dag', 'insert_book_data', 'manual__2024-12-07T18:45:09.543580+00:00', '--job-id', '255', '--raw', '--subdir', 'DAGS_FOLDER/extract.py', '--cfg-path', '/tmp/tmplbqh74iz']
[2024-12-07T18:47:19.858+0000] {standard_task_runner.py:88} INFO - Job 255: Subtask insert_book_data
[2024-12-07T18:47:19.871+0000] {warnings.py:109} WARNING - /home/***/.local/lib/python3.8/site-packages/***/settings.py:194: DeprecationWarning: The sql_alchemy_conn option in [core] has been moved to the sql_alchemy_conn option in [database] - the old setting has been used, but please update your config.
  SQL_ALCHEMY_CONN = conf.get("database", "SQL_ALCHEMY_CONN")

[2024-12-07T18:47:19.904+0000] {task_command.py:423} INFO - Running <TaskInstance: weather_dag.insert_book_data manual__2024-12-07T18:45:09.543580+00:00 [running]> on host 8271fbcad3f4
[2024-12-07T18:47:19.985+0000] {taskinstance.py:2480} INFO - Exporting env vars: AIRFLOW_CTX_DAG_EMAIL='thiernosidybah232@gmail.com' AIRFLOW_CTX_DAG_OWNER='***' AIRFLOW_CTX_DAG_ID='weather_dag' AIRFLOW_CTX_TASK_ID='insert_book_data' AIRFLOW_CTX_EXECUTION_DATE='2024-12-07T18:45:09.543580+00:00' AIRFLOW_CTX_TRY_NUMBER='3' AIRFLOW_CTX_DAG_RUN_ID='manual__2024-12-07T18:45:09.543580+00:00'
[2024-12-07T18:47:20.027+0000] {logging_mixin.py:188} INFO -                        City  ...   Sunset_Local_time
0  Arrondissement de Nantes  ... 2024-12-07 17:16:58

[1 rows x 10 columns]
[2024-12-07T18:47:20.033+0000] {base.py:83} INFO - Using connection ID 'weather_database_connection' for task execution.
[2024-12-07T18:47:20.036+0000] {taskinstance.py:2698} ERROR - Task failed with exception
Traceback (most recent call last):
  File "/home/airflow/.local/lib/python3.8/site-packages/airflow/models/taskinstance.py", line 433, in _execute_task
    result = execute_callable(context=context, **execute_callable_kwargs)
  File "/home/airflow/.local/lib/python3.8/site-packages/airflow/operators/python.py", line 199, in execute
    return_value = self.execute_callable()
  File "/home/airflow/.local/lib/python3.8/site-packages/airflow/operators/python.py", line 216, in execute_callable
    return self.python_callable(*self.op_args, **self.op_kwargs)
  File "/opt/airflow/dags/extract.py", line 87, in insert_book_data_into_postgre
    cursor.execute( insert_query, record)
IndexError: string index out of range
[2024-12-07T18:47:20.041+0000] {taskinstance.py:1138} INFO - Marking task as FAILED. dag_id=weather_dag, task_id=insert_book_data, execution_date=20241207T184509, start_date=20241207T184719, end_date=20241207T184720
[2024-12-07T18:47:20.048+0000] {standard_task_runner.py:107} ERROR - Failed to execute job 255 for task insert_book_data (string index out of range; 10604)
[2024-12-07T18:47:20.068+0000] {local_task_job_runner.py:234} INFO - Task exited with return code 1
[2024-12-07T18:47:20.081+0000] {taskinstance.py:3280} INFO - 0 downstream tasks scheduled from follow-on schedule check
