[2024-12-07T16:15:04.998+0000] {taskinstance.py:1956} INFO - Dependencies all met for dep_context=non-requeueable deps ti=<TaskInstance: weather_dag.insert_book_data manual__2024-12-07T16:13:56.354755+00:00 [queued]>
[2024-12-07T16:15:05.005+0000] {taskinstance.py:1956} INFO - Dependencies all met for dep_context=requeueable deps ti=<TaskInstance: weather_dag.insert_book_data manual__2024-12-07T16:13:56.354755+00:00 [queued]>
[2024-12-07T16:15:05.005+0000] {taskinstance.py:2170} INFO - Starting attempt 2 of 3
[2024-12-07T16:15:05.012+0000] {taskinstance.py:2191} INFO - Executing <Task(PythonOperator): insert_book_data> on 2024-12-07 16:13:56.354755+00:00
[2024-12-07T16:15:05.016+0000] {standard_task_runner.py:60} INFO - Started process 3520 to run task
[2024-12-07T16:15:05.019+0000] {standard_task_runner.py:87} INFO - Running: ['***', 'tasks', 'run', 'weather_dag', 'insert_book_data', 'manual__2024-12-07T16:13:56.354755+00:00', '--job-id', '173', '--raw', '--subdir', 'DAGS_FOLDER/extract.py', '--cfg-path', '/tmp/tmpnv433ldy']
[2024-12-07T16:15:05.021+0000] {standard_task_runner.py:88} INFO - Job 173: Subtask insert_book_data
[2024-12-07T16:15:05.036+0000] {warnings.py:109} WARNING - /home/***/.local/lib/python3.8/site-packages/***/settings.py:194: DeprecationWarning: The sql_alchemy_conn option in [core] has been moved to the sql_alchemy_conn option in [database] - the old setting has been used, but please update your config.
  SQL_ALCHEMY_CONN = conf.get("database", "SQL_ALCHEMY_CONN")

[2024-12-07T16:15:05.075+0000] {task_command.py:423} INFO - Running <TaskInstance: weather_dag.insert_book_data manual__2024-12-07T16:13:56.354755+00:00 [running]> on host 8271fbcad3f4
[2024-12-07T16:15:05.161+0000] {taskinstance.py:2480} INFO - Exporting env vars: AIRFLOW_CTX_DAG_EMAIL='thiernosidybah232@gmail.com' AIRFLOW_CTX_DAG_OWNER='***' AIRFLOW_CTX_DAG_ID='weather_dag' AIRFLOW_CTX_TASK_ID='insert_book_data' AIRFLOW_CTX_EXECUTION_DATE='2024-12-07T16:13:56.354755+00:00' AIRFLOW_CTX_TRY_NUMBER='2' AIRFLOW_CTX_DAG_RUN_ID='manual__2024-12-07T16:13:56.354755+00:00'
[2024-12-07T16:15:05.195+0000] {taskinstance.py:2698} ERROR - Task failed with exception
Traceback (most recent call last):
  File "/home/airflow/.local/lib/python3.8/site-packages/airflow/models/taskinstance.py", line 433, in _execute_task
    result = execute_callable(context=context, **execute_callable_kwargs)
  File "/home/airflow/.local/lib/python3.8/site-packages/airflow/operators/python.py", line 199, in execute
    return_value = self.execute_callable()
  File "/home/airflow/.local/lib/python3.8/site-packages/airflow/operators/python.py", line 216, in execute_callable
    return self.python_callable(*self.op_args, **self.op_kwargs)
  File "/opt/airflow/dags/extract.py", line 85, in insert_book_data_into_postgre
    postgres_hook.run(insert_query, parameters = (col['City'],
TypeError: string indices must be integers
[2024-12-07T16:15:05.203+0000] {taskinstance.py:1138} INFO - Marking task as UP_FOR_RETRY. dag_id=weather_dag, task_id=insert_book_data, execution_date=20241207T161356, start_date=20241207T161504, end_date=20241207T161505
[2024-12-07T16:15:05.216+0000] {standard_task_runner.py:107} ERROR - Failed to execute job 173 for task insert_book_data (string indices must be integers; 3520)
[2024-12-07T16:15:05.230+0000] {local_task_job_runner.py:234} INFO - Task exited with return code 1
[2024-12-07T16:15:05.254+0000] {taskinstance.py:3280} INFO - 0 downstream tasks scheduled from follow-on schedule check
