[2024-12-07T16:17:17.360+0000] {taskinstance.py:1956} INFO - Dependencies all met for dep_context=non-requeueable deps ti=<TaskInstance: weather_dag.insert_book_data manual__2024-12-07T16:17:08.469927+00:00 [queued]>
[2024-12-07T16:17:17.365+0000] {taskinstance.py:1956} INFO - Dependencies all met for dep_context=requeueable deps ti=<TaskInstance: weather_dag.insert_book_data manual__2024-12-07T16:17:08.469927+00:00 [queued]>
[2024-12-07T16:17:17.365+0000] {taskinstance.py:2170} INFO - Starting attempt 1 of 3
[2024-12-07T16:17:17.372+0000] {taskinstance.py:2191} INFO - Executing <Task(PythonOperator): insert_book_data> on 2024-12-07 16:17:08.469927+00:00
[2024-12-07T16:17:17.377+0000] {standard_task_runner.py:60} INFO - Started process 3660 to run task
[2024-12-07T16:17:17.381+0000] {standard_task_runner.py:87} INFO - Running: ['***', 'tasks', 'run', 'weather_dag', 'insert_book_data', 'manual__2024-12-07T16:17:08.469927+00:00', '--job-id', '179', '--raw', '--subdir', 'DAGS_FOLDER/extract.py', '--cfg-path', '/tmp/tmp3nvztwbi']
[2024-12-07T16:17:17.382+0000] {standard_task_runner.py:88} INFO - Job 179: Subtask insert_book_data
[2024-12-07T16:17:17.394+0000] {warnings.py:109} WARNING - /home/***/.local/lib/python3.8/site-packages/***/settings.py:194: DeprecationWarning: The sql_alchemy_conn option in [core] has been moved to the sql_alchemy_conn option in [database] - the old setting has been used, but please update your config.
  SQL_ALCHEMY_CONN = conf.get("database", "SQL_ALCHEMY_CONN")

[2024-12-07T16:17:17.420+0000] {task_command.py:423} INFO - Running <TaskInstance: weather_dag.insert_book_data manual__2024-12-07T16:17:08.469927+00:00 [running]> on host 8271fbcad3f4
[2024-12-07T16:17:17.477+0000] {taskinstance.py:2480} INFO - Exporting env vars: AIRFLOW_CTX_DAG_EMAIL='thiernosidybah232@gmail.com' AIRFLOW_CTX_DAG_OWNER='***' AIRFLOW_CTX_DAG_ID='weather_dag' AIRFLOW_CTX_TASK_ID='insert_book_data' AIRFLOW_CTX_EXECUTION_DATE='2024-12-07T16:17:08.469927+00:00' AIRFLOW_CTX_TRY_NUMBER='1' AIRFLOW_CTX_DAG_RUN_ID='manual__2024-12-07T16:17:08.469927+00:00'
[2024-12-07T16:17:17.507+0000] {taskinstance.py:2698} ERROR - Task failed with exception
Traceback (most recent call last):
  File "/home/airflow/.local/lib/python3.8/site-packages/airflow/models/taskinstance.py", line 433, in _execute_task
    result = execute_callable(context=context, **execute_callable_kwargs)
  File "/home/airflow/.local/lib/python3.8/site-packages/airflow/operators/python.py", line 199, in execute
    return_value = self.execute_callable()
  File "/home/airflow/.local/lib/python3.8/site-packages/airflow/operators/python.py", line 216, in execute_callable
    return self.python_callable(*self.op_args, **self.op_kwargs)
  File "/opt/airflow/dags/extract.py", line 85, in insert_book_data_into_postgre
    postgres_hook.run(insert_query, parameters = (col['City'],
TypeError: string indices must be integers
[2024-12-07T16:17:17.514+0000] {taskinstance.py:1138} INFO - Marking task as UP_FOR_RETRY. dag_id=weather_dag, task_id=insert_book_data, execution_date=20241207T161708, start_date=20241207T161717, end_date=20241207T161717
[2024-12-07T16:17:17.522+0000] {standard_task_runner.py:107} ERROR - Failed to execute job 179 for task insert_book_data (string indices must be integers; 3660)
[2024-12-07T16:17:17.551+0000] {local_task_job_runner.py:234} INFO - Task exited with return code 1
[2024-12-07T16:17:17.562+0000] {taskinstance.py:3280} INFO - 0 downstream tasks scheduled from follow-on schedule check
