[2024-12-06T20:51:10.975+0000] {taskinstance.py:1956} INFO - Dependencies all met for dep_context=non-requeueable deps ti=<TaskInstance: weather_dag.transform_load_weather_data manual__2024-12-06T20:49:00.802575+00:00 [queued]>
[2024-12-06T20:51:10.984+0000] {taskinstance.py:1956} INFO - Dependencies all met for dep_context=requeueable deps ti=<TaskInstance: weather_dag.transform_load_weather_data manual__2024-12-06T20:49:00.802575+00:00 [queued]>
[2024-12-06T20:51:10.985+0000] {taskinstance.py:2170} INFO - Starting attempt 3 of 3
[2024-12-06T20:51:10.998+0000] {taskinstance.py:2191} INFO - Executing <Task(PythonOperator): transform_load_weather_data> on 2024-12-06 20:49:00.802575+00:00
[2024-12-06T20:51:11.005+0000] {standard_task_runner.py:60} INFO - Started process 5474 to run task
[2024-12-06T20:51:11.009+0000] {standard_task_runner.py:87} INFO - Running: ['***', 'tasks', 'run', 'weather_dag', 'transform_load_weather_data', 'manual__2024-12-06T20:49:00.802575+00:00', '--job-id', '26', '--raw', '--subdir', 'DAGS_FOLDER/extract.py', '--cfg-path', '/tmp/tmp3vl8a8vf']
[2024-12-06T20:51:11.011+0000] {standard_task_runner.py:88} INFO - Job 26: Subtask transform_load_weather_data
[2024-12-06T20:51:11.029+0000] {warnings.py:109} WARNING - /home/***/.local/lib/python3.8/site-packages/***/settings.py:194: DeprecationWarning: The sql_alchemy_conn option in [core] has been moved to the sql_alchemy_conn option in [database] - the old setting has been used, but please update your config.
  SQL_ALCHEMY_CONN = conf.get("database", "SQL_ALCHEMY_CONN")

[2024-12-06T20:51:11.083+0000] {task_command.py:423} INFO - Running <TaskInstance: weather_dag.transform_load_weather_data manual__2024-12-06T20:49:00.802575+00:00 [running]> on host 8a5e48d7ee4d
[2024-12-06T20:51:11.194+0000] {taskinstance.py:2480} INFO - Exporting env vars: AIRFLOW_CTX_DAG_EMAIL='thiernosidybah232@gmail.com' AIRFLOW_CTX_DAG_OWNER='***' AIRFLOW_CTX_DAG_ID='weather_dag' AIRFLOW_CTX_TASK_ID='transform_load_weather_data' AIRFLOW_CTX_EXECUTION_DATE='2024-12-06T20:49:00.802575+00:00' AIRFLOW_CTX_TRY_NUMBER='3' AIRFLOW_CTX_DAG_RUN_ID='manual__2024-12-06T20:49:00.802575+00:00'
[2024-12-06T20:51:11.223+0000] {taskinstance.py:2698} ERROR - Task failed with exception
Traceback (most recent call last):
  File "/home/airflow/.local/lib/python3.8/site-packages/airflow/models/taskinstance.py", line 433, in _execute_task
    result = execute_callable(context=context, **execute_callable_kwargs)
  File "/home/airflow/.local/lib/python3.8/site-packages/airflow/operators/python.py", line 199, in execute
    return_value = self.execute_callable()
  File "/home/airflow/.local/lib/python3.8/site-packages/airflow/operators/python.py", line 216, in execute_callable
    return self.python_callable(*self.op_args, **self.op_kwargs)
  File "/opt/airflow/dags/extract.py", line 60, in transform_data
    dataset.to_csv(f"{df_string}.csv", index= False)
  File "/home/airflow/.local/lib/python3.8/site-packages/pandas/core/generic.py", line 3772, in to_csv
    return DataFrameRenderer(formatter).to_csv(
  File "/home/airflow/.local/lib/python3.8/site-packages/pandas/io/formats/format.py", line 1186, in to_csv
    csv_formatter.save()
  File "/home/airflow/.local/lib/python3.8/site-packages/pandas/io/formats/csvs.py", line 240, in save
    with get_handle(
  File "/home/airflow/.local/lib/python3.8/site-packages/pandas/io/common.py", line 737, in get_handle
    check_parent_directory(str(handle))
  File "/home/airflow/.local/lib/python3.8/site-packages/pandas/io/common.py", line 600, in check_parent_directory
    raise OSError(rf"Cannot save file into a non-existent directory: '{parent}'")
OSError: Cannot save file into a non-existent directory: '/my_home'
[2024-12-06T20:51:11.237+0000] {taskinstance.py:1138} INFO - Marking task as FAILED. dag_id=weather_dag, task_id=transform_load_weather_data, execution_date=20241206T204900, start_date=20241206T205110, end_date=20241206T205111
[2024-12-06T20:51:11.252+0000] {standard_task_runner.py:107} ERROR - Failed to execute job 26 for task transform_load_weather_data (Cannot save file into a non-existent directory: '/my_home'; 5474)
[2024-12-06T20:51:11.300+0000] {local_task_job_runner.py:234} INFO - Task exited with return code 1
[2024-12-06T20:51:11.328+0000] {taskinstance.py:3280} INFO - 0 downstream tasks scheduled from follow-on schedule check
