[2024-12-06T22:02:02.593+0000] {taskinstance.py:1956} INFO - Dependencies all met for dep_context=non-requeueable deps ti=<TaskInstance: weather_dag.save_to_csv manual__2024-12-06T21:59:53.777779+00:00 [queued]>
[2024-12-06T22:02:02.600+0000] {taskinstance.py:1956} INFO - Dependencies all met for dep_context=requeueable deps ti=<TaskInstance: weather_dag.save_to_csv manual__2024-12-06T21:59:53.777779+00:00 [queued]>
[2024-12-06T22:02:02.600+0000] {taskinstance.py:2170} INFO - Starting attempt 3 of 3
[2024-12-06T22:02:02.607+0000] {taskinstance.py:2191} INFO - Executing <Task(PythonOperator): save_to_csv> on 2024-12-06 21:59:53.777779+00:00
[2024-12-06T22:02:02.613+0000] {standard_task_runner.py:60} INFO - Started process 8607 to run task
[2024-12-06T22:02:02.617+0000] {standard_task_runner.py:87} INFO - Running: ['***', 'tasks', 'run', 'weather_dag', 'save_to_csv', 'manual__2024-12-06T21:59:53.777779+00:00', '--job-id', '72', '--raw', '--subdir', 'DAGS_FOLDER/extract.py', '--cfg-path', '/tmp/tmpdr2gbzu1']
[2024-12-06T22:02:02.618+0000] {standard_task_runner.py:88} INFO - Job 72: Subtask save_to_csv
[2024-12-06T22:02:02.631+0000] {warnings.py:109} WARNING - /home/***/.local/lib/python3.8/site-packages/***/settings.py:194: DeprecationWarning: The sql_alchemy_conn option in [core] has been moved to the sql_alchemy_conn option in [database] - the old setting has been used, but please update your config.
  SQL_ALCHEMY_CONN = conf.get("database", "SQL_ALCHEMY_CONN")

[2024-12-06T22:02:02.659+0000] {task_command.py:423} INFO - Running <TaskInstance: weather_dag.save_to_csv manual__2024-12-06T21:59:53.777779+00:00 [running]> on host 8a5e48d7ee4d
[2024-12-06T22:02:02.724+0000] {taskinstance.py:2480} INFO - Exporting env vars: AIRFLOW_CTX_DAG_EMAIL='thiernosidybah232@gmail.com' AIRFLOW_CTX_DAG_OWNER='***' AIRFLOW_CTX_DAG_ID='weather_dag' AIRFLOW_CTX_TASK_ID='save_to_csv' AIRFLOW_CTX_EXECUTION_DATE='2024-12-06T21:59:53.777779+00:00' AIRFLOW_CTX_TRY_NUMBER='3' AIRFLOW_CTX_DAG_RUN_ID='manual__2024-12-06T21:59:53.777779+00:00'
[2024-12-06T22:02:02.740+0000] {taskinstance.py:2698} ERROR - Task failed with exception
Traceback (most recent call last):
  File "/home/airflow/.local/lib/python3.8/site-packages/airflow/models/taskinstance.py", line 433, in _execute_task
    result = execute_callable(context=context, **execute_callable_kwargs)
  File "/home/airflow/.local/lib/python3.8/site-packages/airflow/operators/python.py", line 199, in execute
    return_value = self.execute_callable()
  File "/home/airflow/.local/lib/python3.8/site-packages/airflow/operators/python.py", line 216, in execute_callable
    return self.python_callable(*self.op_args, **self.op_kwargs)
  File "/opt/airflow/dags/extract.py", line 87, in save_data
    data.to_csv(csv_path, index= False)
AttributeError: 'NoneType' object has no attribute 'to_csv'
[2024-12-06T22:02:02.752+0000] {taskinstance.py:1138} INFO - Marking task as FAILED. dag_id=weather_dag, task_id=save_to_csv, execution_date=20241206T215953, start_date=20241206T220202, end_date=20241206T220202
[2024-12-06T22:02:02.768+0000] {standard_task_runner.py:107} ERROR - Failed to execute job 72 for task save_to_csv ('NoneType' object has no attribute 'to_csv'; 8607)
[2024-12-06T22:02:02.787+0000] {local_task_job_runner.py:234} INFO - Task exited with return code 1
[2024-12-06T22:02:02.825+0000] {taskinstance.py:3280} INFO - 0 downstream tasks scheduled from follow-on schedule check
