[2024-12-06T21:01:56.565+0000] {taskinstance.py:1956} INFO - Dependencies all met for dep_context=non-requeueable deps ti=<TaskInstance: weather_dag.transform_load_weather_data manual__2024-12-06T20:59:46.322948+00:00 [queued]>
[2024-12-06T21:01:56.576+0000] {taskinstance.py:1956} INFO - Dependencies all met for dep_context=requeueable deps ti=<TaskInstance: weather_dag.transform_load_weather_data manual__2024-12-06T20:59:46.322948+00:00 [queued]>
[2024-12-06T21:01:56.576+0000] {taskinstance.py:2170} INFO - Starting attempt 3 of 3
[2024-12-06T21:01:56.590+0000] {taskinstance.py:2191} INFO - Executing <Task(PythonOperator): transform_load_weather_data> on 2024-12-06 20:59:46.322948+00:00
[2024-12-06T21:01:56.597+0000] {standard_task_runner.py:60} INFO - Started process 5958 to run task
[2024-12-06T21:01:56.602+0000] {standard_task_runner.py:87} INFO - Running: ['***', 'tasks', 'run', 'weather_dag', 'transform_load_weather_data', 'manual__2024-12-06T20:59:46.322948+00:00', '--job-id', '38', '--raw', '--subdir', 'DAGS_FOLDER/extract.py', '--cfg-path', '/tmp/tmpjj44hez0']
[2024-12-06T21:01:56.604+0000] {standard_task_runner.py:88} INFO - Job 38: Subtask transform_load_weather_data
[2024-12-06T21:01:56.619+0000] {warnings.py:109} WARNING - /home/***/.local/lib/python3.8/site-packages/***/settings.py:194: DeprecationWarning: The sql_alchemy_conn option in [core] has been moved to the sql_alchemy_conn option in [database] - the old setting has been used, but please update your config.
  SQL_ALCHEMY_CONN = conf.get("database", "SQL_ALCHEMY_CONN")

[2024-12-06T21:01:56.663+0000] {task_command.py:423} INFO - Running <TaskInstance: weather_dag.transform_load_weather_data manual__2024-12-06T20:59:46.322948+00:00 [running]> on host 8a5e48d7ee4d
[2024-12-06T21:01:56.735+0000] {taskinstance.py:2480} INFO - Exporting env vars: AIRFLOW_CTX_DAG_EMAIL='thiernosidybah232@gmail.com' AIRFLOW_CTX_DAG_OWNER='***' AIRFLOW_CTX_DAG_ID='weather_dag' AIRFLOW_CTX_TASK_ID='transform_load_weather_data' AIRFLOW_CTX_EXECUTION_DATE='2024-12-06T20:59:46.322948+00:00' AIRFLOW_CTX_TRY_NUMBER='3' AIRFLOW_CTX_DAG_RUN_ID='manual__2024-12-06T20:59:46.322948+00:00'
[2024-12-06T21:01:56.752+0000] {taskinstance.py:2698} ERROR - Task failed with exception
Traceback (most recent call last):
  File "/home/airflow/.local/lib/python3.8/site-packages/airflow/models/taskinstance.py", line 433, in _execute_task
    result = execute_callable(context=context, **execute_callable_kwargs)
  File "/home/airflow/.local/lib/python3.8/site-packages/airflow/operators/python.py", line 199, in execute
    return_value = self.execute_callable()
  File "/home/airflow/.local/lib/python3.8/site-packages/airflow/operators/python.py", line 216, in execute_callable
    return self.python_callable(*self.op_args, **self.op_kwargs)
  File "/opt/airflow/dags/extract.py", line 60, in transform_data
    dataset.to_csv(f"{df_string}.csv", index= False)
  File "/home/airflow/.local/lib/python3.8/site-packages/pandas/core/generic.py", line 3772, in to_csv
    return DataFrameRenderer(formatter).to_csv(
  File "/home/airflow/.local/lib/python3.8/site-packages/pandas/io/formats/format.py", line 1186, in to_csv
    csv_formatter.save()
  File "/home/airflow/.local/lib/python3.8/site-packages/pandas/io/formats/csvs.py", line 240, in save
    with get_handle(
  File "/home/airflow/.local/lib/python3.8/site-packages/pandas/io/common.py", line 737, in get_handle
    check_parent_directory(str(handle))
  File "/home/airflow/.local/lib/python3.8/site-packages/pandas/io/common.py", line 600, in check_parent_directory
    raise OSError(rf"Cannot save file into a non-existent directory: '{parent}'")
OSError: Cannot save file into a non-existent directory: '/home/thierno/formation_dataScientest/extract_weather'
[2024-12-06T21:01:56.759+0000] {taskinstance.py:1138} INFO - Marking task as FAILED. dag_id=weather_dag, task_id=transform_load_weather_data, execution_date=20241206T205946, start_date=20241206T210156, end_date=20241206T210156
[2024-12-06T21:01:56.766+0000] {standard_task_runner.py:107} ERROR - Failed to execute job 38 for task transform_load_weather_data (Cannot save file into a non-existent directory: '/home/thierno/formation_dataScientest/extract_weather'; 5958)
[2024-12-06T21:01:56.812+0000] {local_task_job_runner.py:234} INFO - Task exited with return code 1
[2024-12-06T21:01:56.835+0000] {taskinstance.py:3280} INFO - 0 downstream tasks scheduled from follow-on schedule check
