[2024-12-08T12:57:59.126+0000] {taskinstance.py:1956} INFO - Dependencies all met for dep_context=non-requeueable deps ti=<TaskInstance: weather_dag.create_table manual__2024-12-08T12:55:46.561218+00:00 [queued]>
[2024-12-08T12:57:59.135+0000] {taskinstance.py:1956} INFO - Dependencies all met for dep_context=requeueable deps ti=<TaskInstance: weather_dag.create_table manual__2024-12-08T12:55:46.561218+00:00 [queued]>
[2024-12-08T12:57:59.136+0000] {taskinstance.py:2170} INFO - Starting attempt 3 of 3
[2024-12-08T12:57:59.147+0000] {taskinstance.py:2191} INFO - Executing <Task(PostgresOperator): create_table> on 2024-12-08 12:55:46.561218+00:00
[2024-12-08T12:57:59.152+0000] {standard_task_runner.py:60} INFO - Started process 339 to run task
[2024-12-08T12:57:59.155+0000] {standard_task_runner.py:87} INFO - Running: ['***', 'tasks', 'run', 'weather_dag', 'create_table', 'manual__2024-12-08T12:55:46.561218+00:00', '--job-id', '424', '--raw', '--subdir', 'DAGS_FOLDER/extract.py', '--cfg-path', '/tmp/tmp88yr66ib']
[2024-12-08T12:57:59.156+0000] {standard_task_runner.py:88} INFO - Job 424: Subtask create_table
[2024-12-08T12:57:59.171+0000] {warnings.py:109} WARNING - /home/***/.local/lib/python3.8/site-packages/***/settings.py:194: DeprecationWarning: The sql_alchemy_conn option in [core] has been moved to the sql_alchemy_conn option in [database] - the old setting has been used, but please update your config.
  SQL_ALCHEMY_CONN = conf.get("database", "SQL_ALCHEMY_CONN")

[2024-12-08T12:57:59.213+0000] {task_command.py:423} INFO - Running <TaskInstance: weather_dag.create_table manual__2024-12-08T12:55:46.561218+00:00 [running]> on host 08c9c3bec828
[2024-12-08T12:57:59.308+0000] {taskinstance.py:2480} INFO - Exporting env vars: AIRFLOW_CTX_DAG_EMAIL='thiernosidybah232@gmail.com' AIRFLOW_CTX_DAG_OWNER='***' AIRFLOW_CTX_DAG_ID='weather_dag' AIRFLOW_CTX_TASK_ID='create_table' AIRFLOW_CTX_EXECUTION_DATE='2024-12-08T12:55:46.561218+00:00' AIRFLOW_CTX_TRY_NUMBER='3' AIRFLOW_CTX_DAG_RUN_ID='manual__2024-12-08T12:55:46.561218+00:00'
[2024-12-08T12:57:59.309+0000] {sql.py:276} INFO - Executing: 
                        DROP TABLE IF EXISTS Weather_table;
                        CREATE TABLE IF NOT EXISTS Weather_table(
                            city TEXT,
                            weather_description TEXT , 
                            temp_c NUMERIC,
                            feels_like_celsius NUMERIC, 
                            min_temp_c NUMERIC,
                            max_temp_c NUMERIC, 
                            pressure NUMERIC, 
                            humidity NUMERIC, 
                            wind_speed NUMERIC, 
                            time_of_record TIMESTAMP, 
                            sunrise_time TIMESTAMP, 
                            sunset_time TIMESTAMP ); 
                    
[2024-12-08T12:57:59.321+0000] {base.py:83} INFO - Using connection ID 'weather_database_connection' for task execution.
[2024-12-08T12:57:59.331+0000] {base.py:83} INFO - Using connection ID 'weather_database_connection' for task execution.
[2024-12-08T12:57:59.332+0000] {taskinstance.py:2698} ERROR - Task failed with exception
Traceback (most recent call last):
  File "/home/airflow/.local/lib/python3.8/site-packages/airflow/models/taskinstance.py", line 433, in _execute_task
    result = execute_callable(context=context, **execute_callable_kwargs)
  File "/home/airflow/.local/lib/python3.8/site-packages/airflow/providers/common/sql/operators/sql.py", line 282, in execute
    output = hook.run(
  File "/home/airflow/.local/lib/python3.8/site-packages/airflow/providers/common/sql/hooks/sql.py", line 391, in run
    with closing(self.get_conn()) as conn:
  File "/home/airflow/.local/lib/python3.8/site-packages/airflow/providers/postgres/hooks/postgres.py", line 158, in get_conn
    self.conn = psycopg2.connect(**conn_args)
  File "/home/airflow/.local/lib/python3.8/site-packages/psycopg2/__init__.py", line 122, in connect
    conn = _connect(dsn, connection_factory=connection_factory, **kwasync)
psycopg2.OperationalError: connection to server at "172.23.0.3", port 5432 failed: Connection refused
	Is the server running on that host and accepting TCP/IP connections?

[2024-12-08T12:57:59.343+0000] {taskinstance.py:1138} INFO - Marking task as FAILED. dag_id=weather_dag, task_id=create_table, execution_date=20241208T125546, start_date=20241208T125759, end_date=20241208T125759
[2024-12-08T12:57:59.361+0000] {standard_task_runner.py:107} ERROR - Failed to execute job 424 for task create_table (connection to server at "172.23.0.3", port 5432 failed: Connection refused
	Is the server running on that host and accepting TCP/IP connections?
; 339)
[2024-12-08T12:57:59.406+0000] {local_task_job_runner.py:234} INFO - Task exited with return code 1
[2024-12-08T12:57:59.437+0000] {taskinstance.py:3280} INFO - 0 downstream tasks scheduled from follow-on schedule check
