[2024-12-06T22:07:57.233+0000] {taskinstance.py:1956} INFO - Dependencies all met for dep_context=non-requeueable deps ti=<TaskInstance: weather_dag.save_to_csv manual__2024-12-06T22:05:48.308055+00:00 [queued]>
[2024-12-06T22:07:57.244+0000] {taskinstance.py:1956} INFO - Dependencies all met for dep_context=requeueable deps ti=<TaskInstance: weather_dag.save_to_csv manual__2024-12-06T22:05:48.308055+00:00 [queued]>
[2024-12-06T22:07:57.245+0000] {taskinstance.py:2170} INFO - Starting attempt 3 of 3
[2024-12-06T22:07:57.256+0000] {taskinstance.py:2191} INFO - Executing <Task(PythonOperator): save_to_csv> on 2024-12-06 22:05:48.308055+00:00
[2024-12-06T22:07:57.262+0000] {standard_task_runner.py:60} INFO - Started process 8895 to run task
[2024-12-06T22:07:57.264+0000] {standard_task_runner.py:87} INFO - Running: ['***', 'tasks', 'run', 'weather_dag', 'save_to_csv', 'manual__2024-12-06T22:05:48.308055+00:00', '--job-id', '85', '--raw', '--subdir', 'DAGS_FOLDER/extract.py', '--cfg-path', '/tmp/tmpuyubkmvo']
[2024-12-06T22:07:57.264+0000] {standard_task_runner.py:88} INFO - Job 85: Subtask save_to_csv
[2024-12-06T22:07:57.279+0000] {warnings.py:109} WARNING - /home/***/.local/lib/python3.8/site-packages/***/settings.py:194: DeprecationWarning: The sql_alchemy_conn option in [core] has been moved to the sql_alchemy_conn option in [database] - the old setting has been used, but please update your config.
  SQL_ALCHEMY_CONN = conf.get("database", "SQL_ALCHEMY_CONN")

[2024-12-06T22:07:57.321+0000] {task_command.py:423} INFO - Running <TaskInstance: weather_dag.save_to_csv manual__2024-12-06T22:05:48.308055+00:00 [running]> on host 8a5e48d7ee4d
[2024-12-06T22:07:57.433+0000] {taskinstance.py:2480} INFO - Exporting env vars: AIRFLOW_CTX_DAG_EMAIL='thiernosidybah232@gmail.com' AIRFLOW_CTX_DAG_OWNER='***' AIRFLOW_CTX_DAG_ID='weather_dag' AIRFLOW_CTX_TASK_ID='save_to_csv' AIRFLOW_CTX_EXECUTION_DATE='2024-12-06T22:05:48.308055+00:00' AIRFLOW_CTX_TRY_NUMBER='3' AIRFLOW_CTX_DAG_RUN_ID='manual__2024-12-06T22:05:48.308055+00:00'
[2024-12-06T22:07:57.434+0000] {taskinstance.py:2698} ERROR - Task failed with exception
Traceback (most recent call last):
  File "/home/airflow/.local/lib/python3.8/site-packages/airflow/models/taskinstance.py", line 433, in _execute_task
    result = execute_callable(context=context, **execute_callable_kwargs)
  File "/home/airflow/.local/lib/python3.8/site-packages/airflow/operators/python.py", line 199, in execute
    return_value = self.execute_callable()
  File "/home/airflow/.local/lib/python3.8/site-packages/airflow/operators/python.py", line 216, in execute_callable
    return self.python_callable(*self.op_args, **self.op_kwargs)
  File "/opt/airflow/dags/extract.py", line 86, in save_data
    data.to_csv(csv_path, index= False)
AttributeError: 'NoneType' object has no attribute 'to_csv'
[2024-12-06T22:07:57.445+0000] {taskinstance.py:1138} INFO - Marking task as FAILED. dag_id=weather_dag, task_id=save_to_csv, execution_date=20241206T220548, start_date=20241206T220757, end_date=20241206T220757
[2024-12-06T22:07:57.461+0000] {standard_task_runner.py:107} ERROR - Failed to execute job 85 for task save_to_csv ('NoneType' object has no attribute 'to_csv'; 8895)
[2024-12-06T22:07:57.476+0000] {local_task_job_runner.py:234} INFO - Task exited with return code 1
[2024-12-06T22:07:57.499+0000] {taskinstance.py:3280} INFO - 0 downstream tasks scheduled from follow-on schedule check
