[2024-12-07T21:42:00.950+0000] {taskinstance.py:1956} INFO - Dependencies all met for dep_context=non-requeueable deps ti=<TaskInstance: weather_dag.Extract_weather_data manual__2024-12-07T21:39:55.049057+00:00 [queued]>
[2024-12-07T21:42:00.962+0000] {taskinstance.py:1956} INFO - Dependencies all met for dep_context=requeueable deps ti=<TaskInstance: weather_dag.Extract_weather_data manual__2024-12-07T21:39:55.049057+00:00 [queued]>
[2024-12-07T21:42:00.963+0000] {taskinstance.py:2170} INFO - Starting attempt 3 of 3
[2024-12-07T21:42:00.973+0000] {taskinstance.py:2191} INFO - Executing <Task(PythonOperator): Extract_weather_data> on 2024-12-07 21:39:55.049057+00:00
[2024-12-07T21:42:00.981+0000] {standard_task_runner.py:60} INFO - Started process 18804 to run task
[2024-12-07T21:42:00.984+0000] {standard_task_runner.py:87} INFO - Running: ['***', 'tasks', 'run', 'weather_dag', 'Extract_weather_data', 'manual__2024-12-07T21:39:55.049057+00:00', '--job-id', '394', '--raw', '--subdir', 'DAGS_FOLDER/extract.py', '--cfg-path', '/tmp/tmp4q29x3m9']
[2024-12-07T21:42:00.985+0000] {standard_task_runner.py:88} INFO - Job 394: Subtask Extract_weather_data
[2024-12-07T21:42:00.998+0000] {warnings.py:109} WARNING - /home/***/.local/lib/python3.8/site-packages/***/settings.py:194: DeprecationWarning: The sql_alchemy_conn option in [core] has been moved to the sql_alchemy_conn option in [database] - the old setting has been used, but please update your config.
  SQL_ALCHEMY_CONN = conf.get("database", "SQL_ALCHEMY_CONN")

[2024-12-07T21:42:01.038+0000] {task_command.py:423} INFO - Running <TaskInstance: weather_dag.Extract_weather_data manual__2024-12-07T21:39:55.049057+00:00 [running]> on host 8271fbcad3f4
[2024-12-07T21:42:01.127+0000] {taskinstance.py:2480} INFO - Exporting env vars: AIRFLOW_CTX_DAG_EMAIL='thiernosidybah232@gmail.com' AIRFLOW_CTX_DAG_OWNER='***' AIRFLOW_CTX_DAG_ID='weather_dag' AIRFLOW_CTX_TASK_ID='Extract_weather_data' AIRFLOW_CTX_EXECUTION_DATE='2024-12-07T21:39:55.049057+00:00' AIRFLOW_CTX_TRY_NUMBER='3' AIRFLOW_CTX_DAG_RUN_ID='manual__2024-12-07T21:39:55.049057+00:00'
[2024-12-07T21:42:01.129+0000] {taskinstance.py:2698} ERROR - Task failed with exception
Traceback (most recent call last):
  File "/home/airflow/.local/lib/python3.8/site-packages/airflow/models/taskinstance.py", line 433, in _execute_task
    result = execute_callable(context=context, **execute_callable_kwargs)
  File "/home/airflow/.local/lib/python3.8/site-packages/airflow/operators/python.py", line 199, in execute
    return_value = self.execute_callable()
  File "/home/airflow/.local/lib/python3.8/site-packages/airflow/operators/python.py", line 216, in execute_callable
    return self.python_callable(*self.op_args, **self.op_kwargs)
TypeError: extract_data() takes 1 positional argument but 2 were given
[2024-12-07T21:42:01.140+0000] {taskinstance.py:1138} INFO - Marking task as FAILED. dag_id=weather_dag, task_id=Extract_weather_data, execution_date=20241207T213955, start_date=20241207T214200, end_date=20241207T214201
[2024-12-07T21:42:01.153+0000] {standard_task_runner.py:107} ERROR - Failed to execute job 394 for task Extract_weather_data (extract_data() takes 1 positional argument but 2 were given; 18804)
[2024-12-07T21:42:01.198+0000] {local_task_job_runner.py:234} INFO - Task exited with return code 1
[2024-12-07T21:42:01.233+0000] {taskinstance.py:3280} INFO - 0 downstream tasks scheduled from follow-on schedule check
